<?xml version="1.0" ?>
<!-- =================================================================================== -->
<!-- |    This document was autogenerated by xacro from /home/aorthey/devel/ros/stacks/hrp2/hrp2_14_description/urdf/hrp2.xacro | -->
<!-- |    EDITING THIS FILE BY HAND IS NOT RECOMMENDED                                 | -->
<!-- =================================================================================== -->
<!--
   HRP-2 14 URDF model with hands and convex collision model.

   These data are confidential, do *not* publish/distribute this package
   outside of JRL/GEPETTO.
  -->
<robot name="hrp2_14" xmlns:xacro="http://ros.org/wiki/xacro">
  <link name="base_link"/>
  <joint name="WAIST" type="fixed">
    <parent link="base_link"/>
    <child link="BODY"/>
    <origin rpy="0 0 0" xyz="0 -0.1 0.705"/>
  </joint>
  <link name="BODY">
    <inertial>
      <origin rpy="0 0 0" xyz="-0.01435142 0.00000012 0.22307695"/>
      <mass value="15.0295"/>
      <inertia ixx="0.161026" ixy="-0.00000026" ixz="0.00070696" iyy="0.09528" iyz="-0.00000019" izz="0.191914"/>
    </inertial>
    <visual>
      <origin rpy="0 0 0" xyz="0 0 0.003"/>
      <geometry>
        <mesh filename="package://hrp2_14_description/meshes/BODY.dae"/>
      </geometry>
    </visual>
    <collision>
      <origin rpy="0 0 0" xyz="0 0 0.003"/>
      <geometry>
        <mesh filename="package://hrp2_14_description/meshes/convex/BODY.dae"/>
      </geometry>
    </collision>
  </link>
  <joint name="RLEG_JOINT0" type="revolute">
    <parent link="BODY"/>
    <child link="RLEG_LINK0"/>
    <origin rpy="0 0 0" xyz="0 -0.060 0"/>
    <axis xyz="0 0 1"/>
    <limit effort="86.2" lower="-0.785398" upper="0.523599" velocity="3.54108"/>
  </joint>
  <link name="RLEG_LINK0">
    <inertial>
      <origin rpy="0 0 0" xyz="-0.01070336 0.00460716 0.06744546"/>
      <mass value="1.23548000"/>
      <inertia ixx="0.00304689" ixy="-0.00001558" ixz="-0.00055077" iyy="0.00375305" iyz="0.00002250" izz="0.00153874"/>
    </inertial>
    <visual>
      <origin rpy="0 0 0" xyz="0 0 0"/>
      <geometry>
        <mesh filename="package://hrp2_14_description/meshes/RLEG_LINK0.dae"/>
      </geometry>
    </visual>
    <collision>
      <origin rpy="0 0 0" xyz="0 0 0"/>
      <geometry>
        <mesh filename="package://hrp2_14_description/meshes/convex/RLEG_LINK0.dae"/>
      </geometry>
    </collision>
  </link>
  <joint name="RLEG_JOINT1" type="revolute">
    <parent link="RLEG_LINK0"/>
    <child link="RLEG_LINK1"/>
    <origin rpy="0 0 0" xyz="0 0 0"/>
    <axis xyz="1 0 0"/>
    <limit effort="175.4" lower="-0.610865" upper="0.349066" velocity="3.80952"/>
  </joint>
  <link name="RLEG_LINK1">
    <inertial>
      <origin rpy="0 0 0" xyz="-0.00039826 -0.02612872 -0.00292156"/>
      <mass value="0.80553000"/>
      <inertia ixx="0.00126683" ixy="0.00001211" ixz="0.00000164" iyy="0.00050656" iyz="0.00006938" izz="0.00132021"/>
    </inertial>
    <visual>
      <origin rpy="0 0 0" xyz="0 0 0"/>
      <geometry>
        <mesh filename="package://hrp2_14_description/meshes/RLEG_LINK1.dae"/>
      </geometry>
    </visual>
    <collision>
      <origin rpy="0 0 0" xyz="0 0 0"/>
      <geometry>
        <mesh filename="package://hrp2_14_description/meshes/convex/RLEG_LINK1.dae"/>
      </geometry>
    </collision>
  </link>
  <joint name="RLEG_JOINT2" type="revolute">
    <parent link="RLEG_LINK1"/>
    <child link="RLEG_LINK2"/>
    <origin rpy="0 0 0" xyz="0 0 0"/>
    <axis xyz="0 1 0"/>
    <limit effort="151.4" lower="-2.18166" upper="0.733038" velocity="4.42233"/>
  </joint>
  <link name="RLEG_LINK2">
    <inertial>
      <origin rpy="0 0 0" xyz="0.00345946 -0.07794217 -0.15168400"/>
      <mass value="2.07632000"/>
      <inertia ixx="0.02619757" ixy="-0.00003954" ixz="0.00057351" iyy="0.02492350" iyz="0.00067007" izz="0.00376439"/>
    </inertial>
    <visual>
      <origin rpy="0 0 0" xyz="0 0 0"/>
      <geometry>
        <mesh filename="package://hrp2_14_description/meshes/RLEG_LINK2.dae"/>
      </geometry>
    </visual>
    <collision>
      <origin rpy="0 0 0" xyz="0 0 0"/>
      <geometry>
        <mesh filename="package://hrp2_14_description/meshes/convex/RLEG_LINK2.dae"/>
      </geometry>
    </collision>
  </link>
  <joint name="RLEG_JOINT3" type="revolute">
    <parent link="RLEG_LINK2"/>
    <child link="RLEG_LINK3"/>
    <origin rpy="0 0 0" xyz="0 0 -0.300"/>
    <axis xyz="0 1 0"/>
    <limit effort="168.3" lower="-0.0349066" upper="2.61799" velocity="3.9801"/>
  </joint>
  <link name="RLEG_LINK3">
    <inertial>
      <origin rpy="0 0 0" xyz="0.01798781 -0.05791638 -0.13839018"/>
      <mass value="1.74762000"/>
      <inertia ixx="0.02232685" ixy="-0.00009393" ixz="-0.00224776" iyy="0.02250598" iyz="-0.00074527" izz="0.00455443"/>
    </inertial>
    <visual>
      <origin rpy="0 0 0" xyz="0 0 0"/>
      <geometry>
        <mesh filename="package://hrp2_14_description/meshes/RLEG_LINK3.dae"/>
      </geometry>
    </visual>
    <collision>
      <origin rpy="0 0 0" xyz="0 0 0"/>
      <geometry>
        <mesh filename="package://hrp2_14_description/meshes/convex/RLEG_LINK3.dae"/>
      </geometry>
    </collision>
  </link>
  <joint name="RLEG_JOINT4" type="revolute">
    <parent link="RLEG_LINK3"/>
    <child link="RLEG_LINK4"/>
    <origin rpy="0 0 0" xyz="0 -0.035 -0.300"/>
    <axis xyz="0 1 0"/>
    <limit effort="131.6" lower="-1.309" upper="0.733038" velocity="5.07937"/>
  </joint>
  <link name="RLEG_LINK4">
    <inertial>
      <origin rpy="0 0 0" xyz="0.00827083 -0.00133301 -0.00241800"/>
      <mass value="0.65375000"/>
      <inertia ixx="0.00027773" ixy="-0.00000526" ixz="0.00001354" iyy="0.00078966" iyz="-0.00000359" izz="0.00086039"/>
    </inertial>
    <visual>
      <origin rpy="0 0 0" xyz="0 0 0"/>
      <geometry>
        <mesh filename="package://hrp2_14_description/meshes/RLEG_LINK4.dae"/>
      </geometry>
    </visual>
    <collision>
      <origin rpy="0 0 0" xyz="0 0 0"/>
      <geometry>
        <mesh filename="package://hrp2_14_description/meshes/convex/RLEG_LINK4.dae"/>
      </geometry>
    </collision>
  </link>
  <joint name="RLEG_JOINT5" type="revolute">
    <parent link="RLEG_LINK4"/>
    <child link="r_ankle"/>
    <origin rpy="0 -0 0" xyz="0 0 0"/>
    <axis xyz="1 0 0"/>
    <limit effort="73.1" lower="-0.349066" upper="0.610865" velocity="9.14286"/>
  </joint>
  <link name="r_ankle">
    <inertial>
      <origin rpy="0 0 0" xyz="-0.00066419 -0.00468922 -0.06538130"/>
      <mass value="1.63877000"/>
      <inertia ixx="0.00400076" ixy="0.00009983" ixz="0.00079295" iyy="0.00687611" iyz="-0.00018541" izz="0.00711516"/>
    </inertial>
    <visual>
      <origin rpy="0 0 0" xyz="0 0 0"/>
      <geometry>
        <mesh filename="package://hrp2_14_description/meshes/RLEG_LINK5.dae"/>
      </geometry>
    </visual>
    <collision>
      <origin rpy="0 0 0" xyz="0 0 0"/>
      <geometry>
        <mesh filename="package://hrp2_14_description/meshes/convex/RLEG_LINK5.dae"/>
      </geometry>
    </collision>
  </link>
  <joint name="LLEG_JOINT0" type="revolute">
    <parent link="BODY"/>
    <child link="LLEG_LINK0"/>
    <origin rpy="0 0 0" xyz="0 0.060 0"/>
    <axis xyz="0 0 1"/>
    <limit effort="86.2" lower="-0.523599" upper="0.785398" velocity="3.54108"/>
  </joint>
  <link name="LLEG_LINK0">
    <inertial>
      <origin rpy="0 0 0" xyz="-0.01070336 -0.00460716 0.06744546"/>
      <mass value="1.23548000"/>
      <inertia ixx="0.00304689" ixy="0.00001558" ixz="-0.00055077" iyy="0.00375305" iyz="-0.00002250" izz="0.00153874"/>
    </inertial>
    <visual>
      <origin rpy="0 0 0" xyz="0 0 0"/>
      <geometry>
        <mesh filename="package://hrp2_14_description/meshes/LLEG_LINK0.dae"/>
      </geometry>
    </visual>
    <collision>
      <origin rpy="0 0 0" xyz="0 0 0"/>
      <geometry>
        <mesh filename="package://hrp2_14_description/meshes/convex/LLEG_LINK0.dae"/>
      </geometry>
    </collision>
  </link>
  <joint name="LLEG_JOINT1" type="revolute">
    <parent link="LLEG_LINK0"/>
    <child link="LLEG_LINK1"/>
    <origin rpy="0 0 0" xyz="0 0 0"/>
    <axis xyz="1 0 0"/>
    <limit effort="175.4" lower="-0.349066" upper="0.610865" velocity="3.80952"/>
  </joint>
  <link name="LLEG_LINK1">
    <inertial>
      <origin rpy="0 0 0" xyz="-0.00039826 0.02612872 -0.00292156"/>
      <mass value="0.80553000"/>
      <inertia ixx="0.00126683" ixy="-0.00001211" ixz="0.00000164" iyy="0.00050656" iyz="-0.00006938" izz="0.00132021"/>
    </inertial>
    <visual>
      <origin rpy="0 0 0" xyz="0 0 0"/>
      <geometry>
        <mesh filename="package://hrp2_14_description/meshes/LLEG_LINK1.dae"/>
      </geometry>
    </visual>
    <collision>
      <origin rpy="0 0 0" xyz="0 0 0"/>
      <geometry>
        <mesh filename="package://hrp2_14_description/meshes/convex/LLEG_LINK1.dae"/>
      </geometry>
    </collision>
  </link>
  <joint name="LLEG_JOINT2" type="revolute">
    <parent link="LLEG_LINK1"/>
    <child link="LLEG_LINK2"/>
    <origin rpy="0 0 0" xyz="0 0 0"/>
    <axis xyz="0 1 0"/>
    <limit effort="151.4" lower="-2.18166" upper="0.733038" velocity="4.42233"/>
  </joint>
  <link name="LLEG_LINK2">
    <inertial>
      <origin rpy="0 0 0" xyz="0.00345946 0.07794217 -0.15168400"/>
      <mass value="2.07632000"/>
      <inertia ixx="0.02619757" ixy="0.00003954" ixz="0.00057351" iyy="0.02492350" iyz="-0.00067007" izz="0.00376439"/>
    </inertial>
    <visual>
      <origin rpy="0 0 0" xyz="0 0 0"/>
      <geometry>
        <mesh filename="package://hrp2_14_description/meshes/LLEG_LINK2.dae"/>
      </geometry>
    </visual>
    <collision>
      <origin rpy="0 0 0" xyz="0 0 0"/>
      <geometry>
        <mesh filename="package://hrp2_14_description/meshes/convex/LLEG_LINK2.dae"/>
      </geometry>
    </collision>
  </link>
  <joint name="LLEG_JOINT3" type="revolute">
    <parent link="LLEG_LINK2"/>
    <child link="LLEG_LINK3"/>
    <origin rpy="0 0 0" xyz="0 0 -0.300"/>
    <axis xyz="0 1 0"/>
    <limit effort="168.3" lower="-0.0349066" upper="2.61799" velocity="3.9801"/>
  </joint>
  <link name="LLEG_LINK3">
    <inertial>
      <origin rpy="0 0 0" xyz="0.01798781 0.05791638 -0.13839018"/>
      <mass value="1.74762000"/>
      <inertia ixx="0.02232685" ixy="0.00009393" ixz="-0.00224776" iyy="0.02250598" iyz="0.00074527" izz="0.00455443"/>
    </inertial>
    <visual>
      <origin rpy="0 0 0" xyz="0 0 0"/>
      <geometry>
        <mesh filename="package://hrp2_14_description/meshes/LLEG_LINK3.dae"/>
      </geometry>
    </visual>
    <collision>
      <origin rpy="0 0 0" xyz="0 0 0"/>
      <geometry>
        <mesh filename="package://hrp2_14_description/meshes/convex/LLEG_LINK3.dae"/>
      </geometry>
    </collision>
  </link>
  <joint name="LLEG_JOINT4" type="revolute">
    <parent link="LLEG_LINK3"/>
    <child link="LLEG_LINK4"/>
    <origin rpy="0 0 0" xyz="0 0.035 -0.300"/>
    <axis xyz="0 1 0"/>
    <limit effort="131.6" lower="-1.309" upper="0.733038" velocity="5.07937"/>
  </joint>
  <link name="LLEG_LINK4">
    <inertial>
      <origin rpy="0 0 0" xyz="0.00827083 0.00133301 -0.00241800"/>
      <mass value="0.65375000"/>
      <inertia ixx="0.00027773" ixy="0.00000526" ixz="0.00001354" iyy="0.00078966" iyz="0.00000359" izz="0.00086039"/>
    </inertial>
    <visual>
      <origin rpy="0 0 0" xyz="0 0 0"/>
      <geometry>
        <mesh filename="package://hrp2_14_description/meshes/LLEG_LINK4.dae"/>
      </geometry>
    </visual>
    <collision>
      <origin rpy="0 0 0" xyz="0 0 0"/>
      <geometry>
        <mesh filename="package://hrp2_14_description/meshes/convex/LLEG_LINK4.dae"/>
      </geometry>
    </collision>
  </link>
  <joint name="LLEG_JOINT5" type="revolute">
    <parent link="LLEG_LINK4"/>
    <child link="l_ankle"/>
    <origin rpy="0 0 0" xyz="0 0 0"/>
    <axis xyz="1 0 0"/>
    <limit effort="73.1" lower="-0.610865" upper="0.349066" velocity="9.14286"/>
  </joint>
  <link name="l_ankle">
    <inertial>
      <origin rpy="0 0 0" xyz="-0.00066419 0.00468922 -0.06538130"/>
      <mass value="1.63877000"/>
      <inertia ixx="0.00400076" ixy="-0.00009983" ixz="0.00079295" iyy="0.00687611" iyz="0.00018541" izz="0.00711516"/>
    </inertial>
    <visual>
      <origin rpy="0 0 0" xyz="0 0 0"/>
      <geometry>
        <mesh filename="package://hrp2_14_description/meshes/LLEG_LINK5.dae"/>
      </geometry>
    </visual>
    <collision>
      <origin rpy="0 0 0" xyz="0 0 0"/>
      <geometry>
        <mesh filename="package://hrp2_14_description/meshes/convex/LLEG_LINK5.dae"/>
      </geometry>
    </collision>
  </link>
  <joint name="CHEST_JOINT0" type="revolute">
    <parent link="BODY"/>
    <child link="CHEST_LINK0"/>
    <origin rpy="0 0 0" xyz="0.032 0 0.3507"/>
    <axis xyz="0 0 1"/>
    <limit effort="151.1" lower="-0.785398" upper="0.785398" velocity="4.40217"/>
  </joint>
  <link name="CHEST_LINK0">
    <inertial>
      <origin rpy="0 0 0" xyz="-0.01580159 0.00529544 -0.02519634"/>
      <mass value="0.786369"/>
      <inertia ixx="0.00181617" ixy="-0.00007322" ixz="-0.00027731" iyy="0.00185079" iyz="-0.00010749" izz="0.00233207"/>
    </inertial>
    <visual>
      <origin rpy="0 0 0" xyz="0 0 0"/>
      <geometry>
        <mesh filename="package://hrp2_14_description/meshes/CHEST_LINK0.dae"/>
      </geometry>
    </visual>
    <collision>
      <origin rpy="0 0 0" xyz="0 0 0"/>
      <geometry>
        <mesh filename="package://hrp2_14_description/meshes/convex/CHEST_LINK0.dae"/>
      </geometry>
    </collision>
  </link>
  <joint name="CHEST_JOINT1" type="revolute">
    <parent link="CHEST_LINK0"/>
    <child link="torso"/>
    <origin rpy="0 0 0" xyz="0 0 0"/>
    <axis xyz="0 1 0"/>
    <limit effort="278.9" lower="-0.0872665" upper="1.0472" velocity="2.3963"/>
  </joint>
  <link name="torso">
    <inertial>
      <origin rpy="0 0 0" xyz="-0.02904963 0.00716411 0.12102458"/>
      <mass value="11.52457000"/>
      <inertia ixx="0.16047572" ixy="-0.00135932" ixz="-0.00414493" iyy="0.13684576" iyz="0.00388035" izz="0.18166852"/>
    </inertial>
    <visual>
      <origin rpy="0 0 0" xyz="0 0 0"/>
      <geometry>
        <mesh filename="package://hrp2_14_description/meshes/CHEST_LINK1.dae"/>
      </geometry>
    </visual>
    <collision>
      <origin rpy="0 0 0" xyz="0 0 0"/>
      <geometry>
        <mesh filename="package://hrp2_14_description/meshes/convex/CHEST_LINK1.dae"/>
      </geometry>
    </collision>
  </link>
  <joint name="HEAD_JOINT0" type="revolute">
    <parent link="torso"/>
    <child link="HEAD_LINK0"/>
    <origin rpy="0 -0 0" xyz="-0.007 0 0.2973"/>
    <axis xyz="0 0 1"/>
    <limit effort="9.6" lower="-0.785398" upper="0.785398" velocity="6.87679"/>
  </joint>
  <link name="HEAD_LINK0">
    <inertial>
      <origin rpy="0 0 0" xyz="-0.00087533 0.00426199 -0.00802747"/>
      <mass value="0.374766"/>
      <inertia ixx="0.00039945" ixy="-0.00000099" ixz="0.00000226" iyy="0.00022558" iyz="-0.00001181" izz="0.00036246"/>
    </inertial>
    <visual>
      <origin rpy="0 0 0" xyz="0 0 0"/>
      <geometry>
        <mesh filename="package://hrp2_14_description/meshes/HEAD_LINK0.dae"/>
      </geometry>
    </visual>
    <collision>
      <origin rpy="0 0 0" xyz="0 0 0"/>
      <geometry>
        <mesh filename="package://hrp2_14_description/meshes/convex/HEAD_LINK0.dae"/>
      </geometry>
    </collision>
  </link>
  <joint name="HEAD_JOINT1" type="revolute">
    <parent link="HEAD_LINK0"/>
    <child link="HEAD_LINK1"/>
    <origin rpy="0 0 0" xyz="0 0 0"/>
    <axis xyz="0 1 0"/>
    <limit effort="9.6" lower="-0.523599" upper="0.785398" velocity="6.87679"/>
  </joint>
  <link name="HEAD_LINK1">
    <inertial>
      <origin rpy="0 0 0" xyz="0.01298846 0.00008605 0.07876058"/>
      <mass value="0.993355"/>
      <inertia ixx="0.00539717" ixy="-0.00002165" ixz="0.00069330" iyy="0.00457493" iyz="-0.00006372" izz="0.00590682"/>
    </inertial>
    <visual>
      <origin rpy="0 0 0" xyz="0 0 0"/>
      <geometry>
        <mesh filename="package://hrp2_14_description/meshes/HEAD_LINK1.dae"/>
      </geometry>
    </visual>
    <collision>
      <origin rpy="0 0 0" xyz="0 0 0"/>
      <geometry>
        <mesh filename="package://hrp2_14_description/meshes/convex/HEAD_LINK1.dae"/>
      </geometry>
    </collision>
  </link>
  <joint name="RARM_JOINT0" type="revolute">
    <parent link="torso"/>
    <child link="RARM_LINK0"/>
    <origin rpy="0 0 0" xyz="0.008 -0.250 0.181"/>
    <axis xyz="0 1 0"/>
    <limit effort="160.3" lower="-3.14159" upper="1.0472" velocity="4.17044"/>
  </joint>
  <link name="RARM_LINK0">
    <inertial>
      <origin rpy="0 0 0" xyz="-0.00989448 0.0464526 -0.00015316"/>
      <mass value="0.810076"/>
      <inertia ixx="0.00221115" ixy="-0.00030424" ixz="0.00000147" iyy="0.00184189" iyz="0.00004667" izz="0.00344772"/>
    </inertial>
    <visual>
      <origin rpy="0 0 0" xyz="0 0 0"/>
      <geometry>
        <mesh filename="package://hrp2_14_description/meshes/RARM_LINK0.dae"/>
      </geometry>
    </visual>
    <collision>
      <origin rpy="0 0 0" xyz="0 0 0"/>
      <geometry>
        <mesh filename="package://hrp2_14_description/meshes/convex/RARM_LINK0.dae"/>
      </geometry>
    </collision>
  </link>
  <joint name="RARM_JOINT1" type="revolute">
    <parent link="RARM_LINK0"/>
    <child link="RARM_LINK1"/>
    <origin rpy="0 0 0" xyz="0 0 0"/>
    <axis xyz="1 0 0"/>
    <limit effort="100.4" lower="-1.65806" upper="0.174533" velocity="2.4192"/>
  </joint>
  <link name="RARM_LINK1">
    <inertial>
      <origin rpy="0 0 0" xyz="-0.0105646 -0.012043 -0.00948156"/>
      <mass value="1.03448"/>
      <inertia ixx="0.00122098" ixy="0.00028119" ixz="0.00009407" iyy="0.00172216" iyz="0.00012041" izz="0.00161319"/>
    </inertial>
    <visual>
      <origin rpy="0 0 0" xyz="0 0 0"/>
      <geometry>
        <mesh filename="package://hrp2_14_description/meshes/RARM_LINK1.dae"/>
      </geometry>
    </visual>
    <collision>
      <origin rpy="0 0 0" xyz="0 0 0"/>
      <geometry>
        <mesh filename="package://hrp2_14_description/meshes/convex/RARM_LINK1.dae"/>
      </geometry>
    </collision>
  </link>
  <joint name="RARM_JOINT2" type="revolute">
    <parent link="RARM_LINK1"/>
    <child link="RARM_LINK2"/>
    <origin rpy="0 0 0" xyz="0 0 0"/>
    <axis xyz="0 0 1"/>
    <limit effort="48.7" lower="-1.6057" upper="1.6057" velocity="4.15699"/>
  </joint>
  <link name="RARM_LINK2">
    <inertial>
      <origin rpy="0 0 0" xyz="-0.00543072 -0.00479797 -0.166872"/>
      <mass value="1.59929"/>
      <inertia ixx="0.00973049" ixy="-0.00005133" ixz="-0.00019919" iyy="0.00970372" iyz="0.00013747" izz="0.00135331"/>
    </inertial>
    <visual>
      <origin rpy="0 0 0" xyz="0 0 0"/>
      <geometry>
        <mesh filename="package://hrp2_14_description/meshes/RARM_LINK2.dae"/>
      </geometry>
    </visual>
    <collision>
      <origin rpy="0 0 0" xyz="0 0 0"/>
      <geometry>
        <mesh filename="package://hrp2_14_description/meshes/convex/RARM_LINK2.dae"/>
      </geometry>
    </collision>
  </link>
  <joint name="RARM_JOINT3" type="revolute">
    <parent link="RARM_LINK2"/>
    <child link="RARM_LINK3"/>
    <origin rpy="0 0 0" xyz="0 0 -0.250"/>
    <axis xyz="0 1 0"/>
    <limit effort="108.5" lower="-2.3911" upper="0.0349066" velocity="2.23776"/>
  </joint>
  <link name="RARM_LINK3">
    <inertial>
      <origin rpy="0 0 0" xyz="-0.00000927 -0.01616837 -0.06270155"/>
      <mass value="0.77725"/>
      <inertia ixx="0.00232668" ixy="0.00000007" ixz="-0.00000031" iyy="0.00212476" iyz="0.00015097" izz="0.00056363"/>
    </inertial>
    <visual>
      <origin rpy="0 0 0" xyz="0 0 0"/>
      <geometry>
        <mesh filename="package://hrp2_14_description/meshes/RARM_LINK3.dae"/>
      </geometry>
    </visual>
    <collision>
      <origin rpy="0 0 0" xyz="0 0 0"/>
      <geometry>
        <mesh filename="package://hrp2_14_description/meshes/convex/RARM_LINK3.dae"/>
      </geometry>
    </collision>
  </link>
  <joint name="RARM_JOINT4" type="revolute">
    <parent link="RARM_LINK3"/>
    <child link="RARM_LINK4"/>
    <origin rpy="0 0 0" xyz="0 0 -0.250"/>
    <axis xyz="0 0 1"/>
    <limit effort="13.9" lower="-1.6057" upper="1.6057" velocity="4.72794"/>
  </joint>
  <link name="RARM_LINK4">
    <inertial>
      <origin rpy="0 0 0" xyz="-0.00344863 -0.00361759 0.0414959"/>
      <mass value="0.554669"/>
      <inertia ixx="0.00132104" ixy="0.00001646" ixz="0.00004660" iyy="0.00119920" iyz="-0.00011959" izz="0.00031715"/>
    </inertial>
    <visual>
      <origin rpy="0 0 0" xyz="0 0 0"/>
      <geometry>
        <mesh filename="package://hrp2_14_description/meshes/RARM_LINK4.dae"/>
      </geometry>
    </visual>
    <collision>
      <origin rpy="0 0 0" xyz="0 0 0"/>
      <geometry>
        <mesh filename="package://hrp2_14_description/meshes/convex/RARM_LINK4.dae"/>
      </geometry>
    </collision>
  </link>
  <joint name="RARM_JOINT5" type="revolute">
    <parent link="RARM_LINK4"/>
    <child link="r_wrist"/>
    <origin rpy="0 0 0" xyz="0 0 0"/>
    <axis xyz="0 1 0"/>
    <limit effort="18.7" lower="-1.6057" upper="1.6057" velocity="3.16727"/>
  </joint>
  <link name="r_wrist">
    <inertial>
      <origin rpy="0 0 0" xyz="0.0001739 0.0042575 -0.0582954"/>
      <mass value="0.573818"/>
      <inertia ixx="0.00093849" ixy="-0.00000548" ixz="-0.00000817" iyy="0.00102565" iyz="-0.00003239" izz="0.00045951"/>
    </inertial>
    <visual>
      <origin rpy="0 0 0" xyz="0 0 0"/>
      <geometry>
        <mesh filename="package://hrp2_14_description/meshes/RARM_LINK5_full.dae"/>
      </geometry>
    </visual>
    <collision>
      <origin rpy="0 0 0" xyz="0 0 0"/>
      <geometry>
        <mesh filename="package://hrp2_14_description/meshes/convex/RARM_LINK5_full.dae"/>
      </geometry>
    </collision>
  </link>
  <joint name="RARM_JOINT6" type="revolute">
    <parent link="r_wrist"/>
    <child link="RARM_LINK6"/>
    <origin rpy="0 0 0" xyz="0.0 0.020 -0.095"/>
    <axis xyz="1 0 0"/>
    <limit effort="13.9" lower="0" upper="0.785398" velocity="5.68126"/>
  </joint>
  <link name="RARM_LINK6">
    <inertial>
      <origin rpy="0 0 0" xyz="0.01109799 0.00179647 -0.00593392"/>
      <mass value="0.08048559"/>
      <inertia ixx="0.00003264" ixy="-0.00000207" ixz="0.00000583" iyy="0.00003628" iyz="0.00000563" izz="0.00001981"/>
    </inertial>
    <visual>
      <origin rpy="0 0 0" xyz="0 0 0"/>
      <geometry>
        <mesh filename="package://hrp2_14_description/meshes/RARM_LINK6.dae"/>
      </geometry>
    </visual>
    <collision>
      <origin rpy="0 0 0" xyz="0 0 0"/>
      <geometry>
        <mesh filename="package://hrp2_14_description/meshes/convex/RARM_LINK6.dae"/>
      </geometry>
    </collision>
  </link>
  <joint name="RHAND_JOINT0" type="revolute">
    <parent link="RARM_LINK6"/>
    <child link="RHAND_LINK0"/>
    <origin rpy="0 0 0" xyz="0 0 -0.06225397"/>
    <axis xyz="1 0 0"/>
    <limit effort="0" lower="-0.7853981633" upper="0.7853981633" velocity="5.68126"/>
    <mimic joint="RARM_JOINT6" multiplier="-1" offset="0"/>
  </joint>
  <link name="RHAND_LINK0">
    <inertial>
      <origin rpy="0 0 0" xyz="0.01339823 -0.00956484 -0.02146317"/>
      <mass value="0.0632782"/>
      <inertia ixx="0.00001077" ixy="-0.00000180" ixz="-0.00000189" iyy="0.00002338" iyz="-0.00000211" izz="0.00001780"/>
    </inertial>
    <visual>
      <origin rpy="0 0 0" xyz="0 0 0"/>
      <geometry>
        <mesh filename="package://hrp2_14_description/meshes/RHAND_LINK0.dae"/>
      </geometry>
    </visual>
    <collision>
      <origin rpy="0 0 0" xyz="0 0 0"/>
      <geometry>
        <mesh filename="package://hrp2_14_description/meshes/convex/RHAND_LINK0.dae"/>
      </geometry>
    </collision>
  </link>
  <joint name="RHAND_JOINT1" type="revolute">
    <parent link="RHAND_LINK0"/>
    <child link="RHAND_LINK1"/>
    <origin rpy="0 0 0" xyz="0 -0.016 -0.014"/>
    <axis xyz="1 0 0"/>
    <limit effort="0" lower="-0.7853981633" upper="0.7853981633" velocity="5.68126"/>
    <mimic joint="RARM_JOINT6" multiplier="1" offset="0"/>
  </joint>
  <link name="RHAND_LINK1">
    <inertial>
      <origin rpy="0 0 0" xyz="0.00483286 0.01607130 0.03191927"/>
      <mass value="0.07759286"/>
      <inertia ixx="0.00002578" ixy="-0.00000156" ixz="0.00000430" iyy="0.00005577" iyz="0.00000017" izz="0.00004011"/>
    </inertial>
    <visual>
      <origin rpy="0 0 0" xyz="0 0 0"/>
      <geometry>
        <mesh filename="package://hrp2_14_description/meshes/RHAND_LINK1.dae"/>
      </geometry>
    </visual>
    <collision>
      <origin rpy="0 0 0" xyz="0 0 0"/>
      <geometry>
        <mesh filename="package://hrp2_14_description/meshes/convex/RHAND_LINK1.dae"/>
      </geometry>
    </collision>
  </link>
  <joint name="RHAND_JOINT2" type="revolute">
    <parent link="r_wrist"/>
    <child link="RHAND_LINK2"/>
    <origin rpy="0 0 0" xyz="0.0 -0.020 -0.095"/>
    <axis xyz="1 0 0"/>
    <limit effort="0" lower="-0.7853981633" upper="0.7853981633" velocity="5.68126"/>
    <mimic joint="RARM_JOINT6" multiplier="-1" offset="0"/>
  </joint>
  <link name="RHAND_LINK2">
    <inertial>
      <origin rpy="0 0 0" xyz="0.00619820 -0.00085995 -0.00237747"/>
      <mass value="0.20570068"/>
      <inertia ixx="0.00004427" ixy="0.00000182" ixz="0.00000776" iyy="0.00009200" iyz="-0.00000603" izz="0.00007385"/>
    </inertial>
    <visual>
      <origin rpy="0 0 0" xyz="0 0 0"/>
      <geometry>
        <mesh filename="package://hrp2_14_description/meshes/RHAND_LINK2.dae"/>
      </geometry>
    </visual>
    <collision>
      <origin rpy="0 0 0" xyz="0 0 0"/>
      <geometry>
        <mesh filename="package://hrp2_14_description/meshes/convex/RHAND_LINK2.dae"/>
      </geometry>
    </collision>
  </link>
  <joint name="RHAND_JOINT3" type="revolute">
    <parent link="RHAND_LINK2"/>
    <child link="RHAND_LINK3"/>
    <origin rpy="0 0 0" xyz="0 0 -0.062225397"/>
    <axis xyz="1 0 0"/>
    <limit effort="0" lower="-0.7853981633" upper="0.7853981633" velocity="5.68126"/>
    <mimic joint="RARM_JOINT6" multiplier="1" offset="0"/>
  </joint>
  <link name="RHAND_LINK3">
    <inertial>
      <origin rpy="0 0 0" xyz="0.00845438 0.00833957 -0.02261861"/>
      <mass value="0.07456177"/>
      <inertia ixx="0.00001278" ixy="0.00000105" ixz="-0.00000383" iyy="0.00004382" iyz="0.00000165" izz="0.00003649"/>
    </inertial>
    <visual>
      <origin rpy="0 0 0" xyz="0 0 0"/>
      <geometry>
        <mesh filename="package://hrp2_14_description/meshes/RHAND_LINK3.dae"/>
      </geometry>
    </visual>
    <collision>
      <origin rpy="0 0 0" xyz="0 0 0"/>
      <geometry>
        <mesh filename="package://hrp2_14_description/meshes/convex/RHAND_LINK3.dae"/>
      </geometry>
    </collision>
  </link>
  <joint name="RHAND_JOINT4" type="revolute">
    <parent link="RHAND_LINK3"/>
    <child link="RHAND_LINK4"/>
    <origin rpy="0 0 0" xyz="0 0.016 -0.014"/>
    <axis xyz="1 0 0"/>
    <limit effort="0" lower="-0.7853981633" upper="0.7853981633" velocity="5.68126"/>
    <mimic joint="RARM_JOINT6" multiplier="-1" offset="0"/>
  </joint>
  <link name="RHAND_LINK4">
    <inertial>
      <origin rpy="0 0 0" xyz="0.00027217 -0.01767231 0.03091905"/>
      <mass value="0.07102854"/>
      <inertia ixx="0.00002266" ixy="-0.00000044" ixz="0.00000228" iyy="0.00006155" iyz="-0.00000028" izz="0.00004954"/>
    </inertial>
    <visual>
      <origin rpy="0 0 0" xyz="0 0 0"/>
      <geometry>
        <mesh filename="package://hrp2_14_description/meshes/RHAND_LINK4.dae"/>
      </geometry>
    </visual>
    <collision>
      <origin rpy="0 0 0" xyz="0 0 0"/>
      <geometry>
        <mesh filename="package://hrp2_14_description/meshes/convex/RHAND_LINK4.dae"/>
      </geometry>
    </collision>
  </link>
  <joint name="LARM_JOINT0" type="revolute">
    <parent link="torso"/>
    <child link="LARM_LINK0"/>
    <origin rpy="0 0 0" xyz="0.008 0.250 0.181"/>
    <axis xyz="0 1 0"/>
    <limit effort="160.3" lower="-3.14159" upper="1.0472" velocity="4.17044"/>
  </joint>
  <link name="LARM_LINK0">
    <inertial>
      <origin rpy="0 0 0" xyz="-0.00989448 -0.04645260 -0.00015316"/>
      <mass value="0.81007573"/>
      <inertia ixx="0.00221115" ixy="0.00030424" ixz="0.00000147" iyy="0.00184189" iyz="-0.00004667" izz="0.00344772"/>
    </inertial>
    <visual>
      <origin rpy="0 0 0" xyz="0 0 0"/>
      <geometry>
        <mesh filename="package://hrp2_14_description/meshes/LARM_LINK0.dae"/>
      </geometry>
    </visual>
    <collision>
      <origin rpy="0 0 0" xyz="0 0 0"/>
      <geometry>
        <mesh filename="package://hrp2_14_description/meshes/convex/LARM_LINK0.dae"/>
      </geometry>
    </collision>
  </link>
  <joint name="LARM_JOINT1" type="revolute">
    <parent link="LARM_LINK0"/>
    <child link="LARM_LINK1"/>
    <origin rpy="0 0 0" xyz="0 0 0"/>
    <axis xyz="1 0 0"/>
    <limit effort="100.4" lower="-0.174533" upper="1.65806" velocity="2.4192"/>
  </joint>
  <link name="LARM_LINK1">
    <inertial>
      <origin rpy="0 0 0" xyz="-0.01056459 0.01204295 -0.00948156"/>
      <mass value="1.03448000"/>
      <inertia ixx="0.00122098" ixy="-0.00028119" ixz="0.00009407" iyy="0.00172216" iyz="-0.00012041" izz="0.00161319"/>
    </inertial>
    <visual>
      <origin rpy="0 0 0" xyz="0 0 0"/>
      <geometry>
        <mesh filename="package://hrp2_14_description/meshes/LARM_LINK1.dae"/>
      </geometry>
    </visual>
    <collision>
      <origin rpy="0 0 0" xyz="0 0 0"/>
      <geometry>
        <mesh filename="package://hrp2_14_description/meshes/convex/LARM_LINK1.dae"/>
      </geometry>
    </collision>
  </link>
  <joint name="LARM_JOINT2" type="revolute">
    <parent link="LARM_LINK1"/>
    <child link="LARM_LINK2"/>
    <origin rpy="0 0 0" xyz="0 0 0"/>
    <axis xyz="0 0 1"/>
    <limit effort="48.7" lower="-1.6057" upper="1.6057" velocity="4.15699"/>
  </joint>
  <link name="LARM_LINK2">
    <inertial>
      <origin rpy="0 0 0" xyz="-0.00543072 0.00479797 -0.166872"/>
      <mass value="1.59929"/>
      <inertia ixx="0.00973049" ixy="0.00005133" ixz="-0.00019919" iyy="0.00970372" iyz="-0.00013747" izz="0.00135331"/>
    </inertial>
    <visual>
      <origin rpy="0 0 0" xyz="0 0 0"/>
      <geometry>
        <mesh filename="package://hrp2_14_description/meshes/LARM_LINK2.dae"/>
      </geometry>
    </visual>
    <collision>
      <origin rpy="0 0 0" xyz="0 0 0"/>
      <geometry>
        <mesh filename="package://hrp2_14_description/meshes/convex/LARM_LINK2.dae"/>
      </geometry>
    </collision>
  </link>
  <joint name="LARM_JOINT3" type="revolute">
    <parent link="LARM_LINK2"/>
    <child link="LARM_LINK3"/>
    <origin rpy="0 0 0" xyz="0 0 -0.250"/>
    <axis xyz="0 1 0"/>
    <limit effort="108.5" lower="-2.3911" upper="0.0349066" velocity="2.23776"/>
  </joint>
  <link name="LARM_LINK3">
    <inertial>
      <origin rpy="0 0 0" xyz="-0.00000927 0.01616837 -0.06270155"/>
      <mass value="0.77724995"/>
      <inertia ixx="0.00232668" ixy="-0.00000007" ixz="-0.00000031" iyy="0.00212476" iyz="-0.00015097" izz="0.00056363"/>
    </inertial>
    <visual>
      <origin rpy="0 0 0" xyz="0 0 0"/>
      <geometry>
        <mesh filename="package://hrp2_14_description/meshes/LARM_LINK3.dae"/>
      </geometry>
    </visual>
    <collision>
      <origin rpy="0 0 0" xyz="0 0 0"/>
      <geometry>
        <mesh filename="package://hrp2_14_description/meshes/convex/LARM_LINK3.dae"/>
      </geometry>
    </collision>
  </link>
  <joint name="LARM_JOINT4" type="revolute">
    <parent link="LARM_LINK3"/>
    <child link="LARM_LINK4"/>
    <origin rpy="0 0 0" xyz="0 0 -0.250"/>
    <axis xyz="0 0 1"/>
    <limit effort="13.9" lower="-1.6057" upper="1.6057" velocity="4.72794"/>
  </joint>
  <link name="LARM_LINK4">
    <inertial>
      <origin rpy="0 0 0" xyz="0.00247694 0.00361759 0.04149589"/>
      <mass value="0.55466858"/>
      <inertia ixx="0.00132103" ixy="0.00000930" ixz="-0.00003617" iyy="0.00119868" iyz="0.00011959" izz="0.00031664"/>
    </inertial>
    <visual>
      <origin rpy="0 0 0" xyz="0 0 0"/>
      <geometry>
        <mesh filename="package://hrp2_14_description/meshes/LARM_LINK4.dae"/>
      </geometry>
    </visual>
    <collision>
      <origin rpy="0 0 0" xyz="0 0 0"/>
      <geometry>
        <mesh filename="package://hrp2_14_description/meshes/convex/LARM_LINK4.dae"/>
      </geometry>
    </collision>
  </link>
  <joint name="LARM_JOINT5" type="revolute">
    <parent link="LARM_LINK4"/>
    <child link="l_wrist"/>
    <origin rpy="0 0 0" xyz="0 0 0"/>
    <axis xyz="0 1 0"/>
    <limit effort="18.7" lower="-1.6057" upper="1.6057" velocity="3.16727"/>
  </joint>
  <link name="l_wrist">
    <inertial>
      <origin rpy="0 0 0" xyz="0.00017390 -0.00425750 -0.05829538"/>
      <mass value="0.57381789"/>
      <inertia ixx="0.00093849" ixy="0.00000548" ixz="-0.00000817" iyy="0.00102565" iyz="0.00003239" izz="0.00045951"/>
    </inertial>
    <visual>
      <origin rpy="0 0 0" xyz="0 0 0"/>
      <geometry>
        <mesh filename="package://hrp2_14_description/meshes/LARM_LINK5_full.dae"/>
      </geometry>
    </visual>
    <collision>
      <origin rpy="0 0 0" xyz="0 0 0"/>
      <geometry>
        <mesh filename="package://hrp2_14_description/meshes/convex/LARM_LINK5_full.dae"/>
      </geometry>
    </collision>
  </link>
  <joint name="LARM_JOINT6" type="revolute">
    <parent link="l_wrist"/>
    <child link="LARM_LINK6"/>
    <origin rpy="0 0 0" xyz="0.0 -0.020 -0.095"/>
    <axis xyz="-1 0 0"/>
    <limit effort="13.9" lower="-0.785398" upper="0.785398" velocity="5.68126"/>
  </joint>
  <link name="LARM_LINK6">
    <inertial>
      <origin rpy="0 0 0" xyz="0.01109799 -0.00179647 -0.00593392"/>
      <mass value="0.08048559"/>
      <inertia ixx="0.00003264" ixy="0.00000207" ixz="0.00000583" iyy="0.00003628" iyz="-0.00000563" izz="0.00001981"/>
    </inertial>
    <visual>
      <origin rpy="0 0 3.141592654" xyz="0 0 0"/>
      <geometry>
        <mesh filename="package://hrp2_14_description/meshes/LARM_LINK6.dae"/>
      </geometry>
    </visual>
    <collision>
      <origin rpy="0 0 3.141592654" xyz="0 0 0"/>
      <geometry>
        <mesh filename="package://hrp2_14_description/meshes/convex/LARM_LINK6.dae"/>
      </geometry>
    </collision>
  </link>
  <joint name="LHAND_JOINT0" type="revolute">
    <parent link="LARM_LINK6"/>
    <child link="LHAND_LINK0"/>
    <origin rpy="0 0 0" xyz="0 0 -0.06225397"/>
    <axis xyz="-1 0 0"/>
    <limit effort="0" lower="-0.7853981633" upper="0.7853981633" velocity="5.68126"/>
    <mimic joint="LARM_JOINT6" multiplier="-1" offset="0"/>
  </joint>
  <link name="LHAND_LINK0">
    <inertial>
      <origin rpy="0 0 0" xyz="0.01339823 0.00956484 -0.02146317"/>
      <mass value="0.06327816"/>
      <inertia ixx="0.00001077" ixy="0.00000180" ixz="-0.00000189" iyy="0.00002338" iyz="0.00000211" izz="0.00001780"/>
    </inertial>
    <visual>
      <origin rpy="0 0 3.141592654" xyz="0 0 0"/>
      <geometry>
        <mesh filename="package://hrp2_14_description/meshes/LHAND_LINK0.dae"/>
      </geometry>
    </visual>
    <collision>
      <origin rpy="0 0 3.141592654" xyz="0 0 0"/>
      <geometry>
        <mesh filename="package://hrp2_14_description/meshes/convex/LHAND_LINK0.dae"/>
      </geometry>
    </collision>
  </link>
  <joint name="LHAND_JOINT1" type="revolute">
    <parent link="LHAND_LINK0"/>
    <child link="LHAND_LINK1"/>
    <origin rpy="0 0 0" xyz="0 0.016 -0.014"/>
    <axis xyz="-1 0 0"/>
    <limit effort="0" lower="-0.7853981633" upper="0.7853981633" velocity="5.68126"/>
    <mimic joint="LARM_JOINT6" multiplier="1" offset="0"/>
  </joint>
  <link name="LHAND_LINK1">
    <inertial>
      <origin rpy="0 0 0" xyz="0.00483286 -0.01607130 0.03191927"/>
      <mass value="0.07759286"/>
      <inertia ixx="0.00002578" ixy="0.00000156" ixz="0.00000430" iyy="0.00005577" iyz="-0.00000017" izz="0.00004011"/>
    </inertial>
    <visual>
      <origin rpy="0 0 3.141592654" xyz="0 0 0"/>
      <geometry>
        <mesh filename="package://hrp2_14_description/meshes/LHAND_LINK1.dae"/>
      </geometry>
    </visual>
    <collision>
      <origin rpy="0 0 3.141592654" xyz="0 0 0"/>
      <geometry>
        <mesh filename="package://hrp2_14_description/meshes/convex/LHAND_LINK1.dae"/>
      </geometry>
    </collision>
  </link>
  <joint name="LHAND_JOINT2" type="revolute">
    <parent link="l_wrist"/>
    <child link="LHAND_LINK2"/>
    <origin rpy="0 0 0" xyz="0.0 0.020 -0.095"/>
    <axis xyz="-1 0 0"/>
    <limit effort="0" lower="-0.7853981633" upper="0.7853981633" velocity="5.68126"/>
    <mimic joint="LARM_JOINT6" multiplier="-1" offset="0"/>
  </joint>
  <link name="LHAND_LINK2">
    <inertial>
      <origin rpy="0 0 0" xyz="0.00619820 0.00085995 -0.00237747"/>
      <mass value="0.20570068"/>
      <inertia ixx="0.00004427" ixy="-0.00000182" ixz="0.00000776" iyy="0.00009200" iyz="0.00000603" izz="0.00007385"/>
    </inertial>
    <visual>
      <origin rpy="0 0 3.141592654" xyz="0 0 0"/>
      <geometry>
        <mesh filename="package://hrp2_14_description/meshes/LHAND_LINK2.dae"/>
      </geometry>
    </visual>
    <collision>
      <origin rpy="0 0 3.141592654" xyz="0 0 0"/>
      <geometry>
        <mesh filename="package://hrp2_14_description/meshes/convex/LHAND_LINK2.dae"/>
      </geometry>
    </collision>
  </link>
  <joint name="LHAND_JOINT3" type="revolute">
    <parent link="LHAND_LINK2"/>
    <child link="LHAND_LINK3"/>
    <origin rpy="0 0 0" xyz="0 0 -0.062225397"/>
    <axis xyz="-1 0 0"/>
    <limit effort="0" lower="-0.7853981633" upper="0.7853981633" velocity="5.68126"/>
    <mimic joint="LARM_JOINT6" multiplier="1" offset="0"/>
  </joint>
  <link name="LHAND_LINK3">
    <inertial>
      <origin rpy="0 0 0" xyz="0.00845438 -0.00833957 -0.02261861"/>
      <mass value="0.07456177"/>
      <inertia ixx="0.00001278" ixy="-0.00000105" ixz="-0.00000383" iyy="0.00004382" iyz="-0.00000165" izz="0.00003649"/>
    </inertial>
    <visual>
      <origin rpy="0 0 3.141592654" xyz="0 0 0"/>
      <geometry>
        <mesh filename="package://hrp2_14_description/meshes/LHAND_LINK3.dae"/>
      </geometry>
    </visual>
    <collision>
      <origin rpy="0 0 3.141592654" xyz="0 0 0"/>
      <geometry>
        <mesh filename="package://hrp2_14_description/meshes/convex/LHAND_LINK3.dae"/>
      </geometry>
    </collision>
  </link>
  <joint name="LHAND_JOINT4" type="revolute">
    <parent link="LHAND_LINK3"/>
    <child link="LHAND_LINK4"/>
    <origin rpy="0 0 0" xyz="0 -0.016 -0.014"/>
    <axis xyz="-1 0 0"/>
    <limit effort="0" lower="-0.7853981633" upper="0.7853981633" velocity="5.68126"/>
    <mimic joint="LARM_JOINT6" multiplier="-1" offset="0"/>
  </joint>
  <link name="LHAND_LINK4">
    <inertial>
      <origin rpy="0 0 0" xyz="0.00027217 0.01767231 0.03091905"/>
      <mass value="0.07102854"/>
      <inertia ixx="0.00002266" ixy="0.00000044" ixz="0.00000228" iyy="0.00006155" iyz="0.00000028" izz="0.00004954"/>
    </inertial>
    <visual>
      <origin rpy="0 0 3.141592654" xyz="0 0 0"/>
      <geometry>
        <mesh filename="package://hrp2_14_description/meshes/LHAND_LINK4.dae"/>
      </geometry>
    </visual>
    <collision>
      <origin rpy="0 0 3.141592654" xyz="0 0 0"/>
      <geometry>
        <mesh filename="package://hrp2_14_description/meshes/convex/LHAND_LINK4.dae"/>
      </geometry>
    </collision>
  </link>
  <joint name="AccelerometerJoint" type="fixed">
    <parent link="torso"/>
    <child link="Accelerometer"/>
    <origin rpy="0 0 0" xyz="-0.13 0 0.118"/>
  </joint>
  <link name="Accelerometer"/>
  <joint name="GyroJoint" type="fixed">
    <parent link="torso"/>
    <child link="Gyro"/>
    <origin rpy="0 0 0" xyz="-0.13 0 0.118"/>
  </joint>
  <link name="Gyro"/>
  <joint name="RightFootForceSensorJoint" type="fixed">
    <parent link="r_ankle"/>
    <child link="RightFootForceSensor"/>
    <origin rpy="0 0 0" xyz="0 0 -0.105"/>
    <!-- FIXME: missing rotation -->
  </joint>
  <link name="RightFootForceSensor"/>
  <joint name="LeftFootForceSensorJoint" type="fixed">
    <parent link="l_ankle"/>
    <child link="LeftFootForceSensor"/>
    <origin rpy="0 0 0" xyz="0 0 -0.105"/>
    <!-- FIXME: missing rotation -->
  </joint>
  <link name="LeftFootForceSensor"/>
  <joint name="RightHandForceSensorJoint" type="fixed">
    <parent link="r_wrist"/>
    <child link="RightHandForceSensor"/>
    <origin rpy="0 0 0" xyz="0.005 0 -0.05925"/>
    <!-- FIXME: missing rotation -->
  </joint>
  <link name="RightHandForceSensor"/>
  <joint name="LeftHandForceSensorJoint" type="fixed">
    <parent link="l_wrist"/>
    <child link="LeftHandForceSensor"/>
    <origin rpy="0 0 0" xyz="0.005 0 -0.05925"/>
    <!-- FIXME: missing rotation -->
  </joint>
  <link name="LeftHandForceSensor"/>
  <joint name="camera_top_left_joint" type="fixed">
    <parent link="HEAD_LINK1"/>
    <child link="camera_top_left"/>
    <origin rpy="0.046180938822255588 0.27302126551042288 0.034167218898384179" xyz="0.07407829  0.02659051  0.14177429"/>
  </joint>
  <link name="camera_top_left"/>
  <joint name="camera_top_left_optical_joint" type="fixed">
    <parent link="camera_top_left"/>
    <child link="camera_top_left_optical"/>
    <origin rpy="-1.57079633 0 -1.57079633" xyz="0 0 0"/>
  </joint>
  <link name="camera_top_left_optical"/>
  <joint name="camera_top_right_joint" type="fixed">
    <parent link="HEAD_LINK1"/>
    <child link="camera_top_right"/>
    <origin rpy="-0.0079854413849446259 0.22011162662996947 0.0058911638910028805" xyz="0.07235902 -0.03327363  0.1353676"/>
  </joint>
  <link name="camera_top_right"/>
  <joint name="camera_top_right_optical_joint" type="fixed">
    <parent link="camera_top_right"/>
    <child link="camera_top_right_optical"/>
    <origin rpy="-1.57079633 0 -1.57079633" xyz="0 0 0"/>
  </joint>
  <link name="camera_top_right_optical"/>
  <joint name="camera_bottom_left_joint" type="fixed">
    <parent link="HEAD_LINK1"/>
    <child link="camera_bottom_left"/>
    <origin rpy="-0.0079854413849446259 0.22011162662996947 0.0058911638910028805" xyz="0.08118668  0.06998529  0.05699587"/>
  </joint>
  <link name="camera_bottom_left"/>
  <joint name="camera_bottom_left_optical_joint" type="fixed">
    <parent link="camera_bottom_left"/>
    <child link="camera_bottom_left_optical"/>
    <origin rpy="-1.57079633 0 -1.57079633" xyz="0 0 0"/>
  </joint>
  <link name="camera_bottom_left_optical"/>
  <joint name="camera_bottom_right_joint" type="fixed">
    <parent link="HEAD_LINK1"/>
    <child link="camera_bottom_right"/>
    <origin rpy="0.010978531384526875 0.22194796815506787 -0.0095059405913152043" xyz="0.07660117 -0.0759482   0.05529225"/>
  </joint>
  <link name="camera_bottom_right"/>
  <joint name="camera_bottom_right_optical_joint" type="fixed">
    <parent link="camera_bottom_right"/>
    <child link="camera_bottom_right_optical"/>
    <origin rpy="-1.57079633 0 -1.57079633" xyz="0 0 0"/>
  </joint>
  <link name="camera_bottom_right_optical"/>
  <joint name="l_gripper_joint" type="fixed">
    <parent link="l_wrist"/>
    <child link="l_gripper"/>
    <origin rpy="-1.57079633 0 0" xyz="0 0 -0.17"/>
  </joint>
  <link name="l_gripper"/>
  <joint name="r_gripper_joint" type="fixed">
    <parent link="r_wrist"/>
    <child link="r_gripper"/>
    <origin rpy="-1.57079633 0 0" xyz="0 0 -0.17"/>
  </joint>
  <link name="r_gripper"/>
  <joint name="l_sole_joint" type="fixed">
    <parent link="l_ankle"/>
    <child link="l_sole"/>
    <origin rpy="0 0 0" xyz="0 0 -0.105"/>
  </joint>
  <link name="l_sole"/>
  <joint name="r_sole_joint" type="fixed">
    <parent link="r_ankle"/>
    <child link="r_sole"/>
    <origin rpy="0 0 0" xyz="0 0 -0.105"/>
  </joint>
  <link name="r_sole"/>
  <joint name="gaze_joint" type="fixed">
    <parent link="HEAD_LINK1"/>
    <child link="gaze"/>
    <origin rpy="0 0.174 0" xyz="0 0 0.118"/>
  </joint>
  <link name="gaze"/>
</robot>

